Workbook
Name Store_Type: 'Setup_Parameters'!$B$4
Name ASP_Value: 'Setup_Parameters'!$E$4
Name Speed_Weights: 'Setup_Parameters'!$B$8:$B$10
Name Space_Weights: 'Setup_Parameters'!$C$8:$C$10
Name Benchmark_Scores: 'Setup_Parameters'!$B$14:$B$16
Name Overall_Score: 'Calc_Engine'!$B$11
Name Performance_Grade: 'Calc_Engine'!$B$12
Name Monthly_Leakage: 'Calc_Engine'!$B$17
Name Metric_Report_Range: 'Calc_Engine'!$A$21:$E$32
Name Red_Flag_Vector: 'Calc_Engine'!$F$21:$F$32
Name CX_Score_Overall: 'Calc_Engine'!$E$5
Name Ops_Score_Overall: 'Calc_Engine'!$E$6
Name Rev_Score_Overall: 'Calc_Engine'!$E$7
Name Lost_Customers_Daily: 'Input_Data'!$D$51

Sheet Setup_Parameters
A1: CAFÉ AUDIT SYSTEM · Setup & Configuration Parameters
A3: 1 AUDIT CONFIGURATION
A4: Store Type | B4: Speed-First | C4: Base ASP | D4: (average spend per customer — local currency) | E4: 4.5
A6: 2 DIMENSION WEIGHT MATRIX
A7: Dimension | B7: Speed-First Weight | C7: Space-First Weight | D7: Covers
A8: Customer Experience (CX) | B8: 0.3 | C8: 0.5 | D8: Service friendliness, queue time, order accuracy, atmosphere
A9: Operations (Ops) | B9: 0.4 | C9: 0.3 | D9: Barista workflow, equipment, cleanliness, stock availability
A10: Revenue Opportunity (Rev) | B10: 0.3 | C10: 0.2 | D10: Menu upselling, capacity utilization, pricing, secondary spend
A12: 3 INDUSTRY BENCHMARK TARGETS (used by Radar Chart on Dashboard)
A13: Dimension | B13: Benchmark Score (0-5) | C13: Interpretation
A14: Customer Experience (CX) | B14: 4 | C14: Minimum acceptable CX performance
A15: Operations (Ops) | B15: 3.8 | C15: Operational efficiency baseline
A16: Revenue Opportunity (Rev) | B16: 3.5 | C16: Revenue capture baseline
A18: 4 METRIC DEFINITIONS & REMEDIES
A19: Metric ID | B19: Dimension | C19: Metric Name | D19: Recommended Action / Remedy
A20: CX_001 | B20: CX | C20: Service Friendliness | D20: Implement service standards training. Introduce daily briefing for hospitality KPIs.
A21: CX_002 | B21: CX | C21: Queue & Wait Time | D21: Deploy queue management system. Train staff on proactive ETA communication.
A22: CX_003 | B22: CX | C22: Order Accuracy | D22: Introduce order verification checklist. Review drink ticketing workflow end-to-end.
A23: CX_004 | B23: CX | C23: Atmosphere & Seating | D23: Conduct seating audit. Address noise and temperature. Schedule deep-clean cycle.
A24: OPS_001 | B24: Ops | C24: Barista Workflow Efficiency | D24: Map current workflow. Implement station layout redesign. Cross-train all staff.
A25: OPS_002 | B25: Ops | C25: Equipment Reliability | D25: Schedule preventive maintenance. Build equipment checklist. Source backup units.
A26: OPS_003 | B26: Ops | C26: Counter Cleanliness | D26: Implement hourly cleaning schedule. Assign counter ownership per staff member.
A27: OPS_004 | B27: Ops | C27: Menu & Stock Availability | D27: Deploy real-time inventory tracking. Implement 80/20 par-level restocking system.
A28: REV_001 | B28: Rev | C28: Menu Visibility & Upselling | D28: Redesign menu board layout. Script upsell prompts. Introduce combo promotions.
A29: REV_002 | B29: Rev | C29: Peak Capacity Utilization | D29: Implement reservation or queue-ahead system. Install peak-hour promotional signage.
A30: REV_003 | B30: Rev | C30: Pricing Perception | D30: Review pricing vs local competitive set. Strengthen premium product storytelling.
A31: REV_004 | B31: Rev | C31: Secondary Spend Opportunity | D31: Introduce grab-and-go retail section. Train staff on cross-selling protocol.
A33: 5 SCORING RUBRIC DICTIONARY · Key format: Metric_ID_Score (e.g. CX_001_3)
A34: Key (Metric_ID_Score) | B34: Scoring Criteria Description
A35: CX_001_1 | B35: Staff dismissive or rude; customers ignored or poorly treated throughout
A36: CX_001_2 | B36: Minimal acknowledgment; interactions purely transactional; no warmth
A37: CX_001_3 | B37: Polite and professional; basic greeting and thank-you consistently delivered
A38: CX_001_4 | B38: Warm and engaged; staff proactively helpful; personal touch observed
A39: CX_001_5 | B39: Outstanding hospitality; every interaction memorable; zero negative moments
A40: CX_002_1 | B40: Wait exceeds 10 minutes; no queue visibility or management observed
A41: CX_002_2 | B41: Wait 7-10 min; customers not informed of expected delay
A42: CX_002_3 | B42: Wait 4-6 min; staff aware of queue; no proactive communication
A43: CX_002_4 | B43: Wait 2-3 min; queue actively managed; ETAs communicated when asked
A44: CX_002_5 | B44: Wait under 2 minutes; no visible bottleneck at any point during shift
A45: CX_003_1 | B45: Multiple order errors observed; no systematic correction process
...

Sheet Input_Data
A1: CAFÉ AUDIT TOOL · On-Site Observation Form · All shifts, tablet-optimised
A2: Café Name: | C2: Audit Date: | E2: Auditor:
A3: Store Type: | B3: =Setup_Parameters!$B$4 | C3: <-- Controlled by Setup_Parameters!B4. Do not edit this cell.
A5: SHIFT 1: MORNING PEAK (08:00 – 10:00)
A6: Metric ID | B6: Dimension | C6: Metric Name | D6: Score (1-5) | E6: Scoring Criteria | F6: Auditor Notes
A7: CX_001 | B7: CX | C7: Service Friendliness | E7: =IFERROR(XLOOKUP(A7&"_"&TEXT(D7,"0"),Setup_Parameters!$A$35:$A$94,Setup_Parameters!$B$35:$B$94,"Select a score (1-5) to display scoring criteria"),"")
A8: CX_002 | B8: CX | C8: Queue & Wait Time | E8: =IFERROR(XLOOKUP(A8&"_"&TEXT(D8,"0"),Setup_Parameters!$A$35:$A$94,Setup_Parameters!$B$35:$B$94,"Select a score (1-5) to display scoring criteria"),"")
A9: CX_003 | B9: CX | C9: Order Accuracy | E9: =IFERROR(XLOOKUP(A9&"_"&TEXT(D9,"0"),Setup_Parameters!$A$35:$A$94,Setup_Parameters!$B$35:$B$94,"Select a score (1-5) to display scoring criteria"),"")
A10: CX_004 | B10: CX | C10: Atmosphere & Seating | E10: =IFERROR(XLOOKUP(A10&"_"&TEXT(D10,"0"),Setup_Parameters!$A$35:$A$94,Setup_Parameters!$B$35:$B$94,"Select a score (1-5) to display scoring criteria"),"")
A11: OPS_001 | B11: Ops | C11: Barista Workflow Efficiency | E11: =IFERROR(XLOOKUP(A11&"_"&TEXT(D11,"0"),Setup_Parameters!$A$35:$A$94,Setup_Parameters!$B$35:$B$94,"Select a score (1-5) to display scoring criteria"),"")
A12: OPS_002 | B12: Ops | C12: Equipment Reliability | E12: =IFERROR(XLOOKUP(A12&"_"&TEXT(D12,"0"),Setup_Parameters!$A$35:$A$94,Setup_Parameters!$B$35:$B$94,"Select a score (1-5) to display scoring criteria"),"")
A13: OPS_003 | B13: Ops | C13: Counter Cleanliness | E13: =IFERROR(XLOOKUP(A13&"_"&TEXT(D13,"0"),Setup_Parameters!$A$35:$A$94,Setup_Parameters!$B$35:$B$94,"Select a score (1-5) to display scoring criteria"),"")
A14: OPS_004 | B14: Ops | C14: Menu & Stock Availability | E14: =IFERROR(XLOOKUP(A14&"_"&TEXT(D14,"0"),Setup_Parameters!$A$35:$A$94,Setup_Parameters!$B$35:$B$94,"Select a score (1-5) to display scoring criteria"),"")
A15: REV_001 | B15: Rev | C15: Menu Visibility & Upselling | E15: =IFERROR(XLOOKUP(A15&"_"&TEXT(D15,"0"),Setup_Parameters!$A$35:$A$94,Setup_Parameters!$B$35:$B$94,"Select a score (1-5) to display scoring criteria"),"")
A16: REV_002 | B16: Rev | C16: Peak Capacity Utilization | E16: =IFERROR(XLOOKUP(A16&"_"&TEXT(D16,"0"),Setup_Parameters!$A$35:$A$94,Setup_Parameters!$B$35:$B$94,"Select a score (1-5) to display scoring criteria"),"")
A17: REV_003 | B17: Rev | C17: Pricing Perception | E17: =IFERROR(XLOOKUP(A17&"_"&TEXT(D17,"0"),Setup_Parameters!$A$35:$A$94,Setup_Parameters!$B$35:$B$94,"Select a score (1-5) to display scoring criteria"),"")
A18: REV_004 | B18: Rev | C18: Secondary Spend Opportunity | E18: =IFERROR(XLOOKUP(A18&"_"&TEXT(D18,"0"),Setup_Parameters!$A$35:$A$94,Setup_Parameters!$B$35:$B$94,"Select a score (1-5) to display scoring criteria"),"")
A20: SHIFT 2: AFTERNOON RUSH (14:00 – 16:00)
A21: Metric ID | B21: Dimension | C21: Metric Name | D21: Score (1-5) | E21: Scoring Criteria | F21: Auditor Notes
A22: CX_001 | B22: CX | C22: Service Friendliness | E22: =IFERROR(XLOOKUP(A22&"_"&TEXT(D22,"0"),Setup_Parameters!$A$35:$A$94,Setup_Parameters!$B$35:$B$94,"Select a score (1-5) to display scoring criteria"),"")
A23: CX_002 | B23: CX | C23: Queue & Wait Time | E23: =IFERROR(XLOOKUP(A23&"_"&TEXT(D23,"0"),Setup_Parameters!$A$35:$A$94,Setup_Parameters!$B$35:$B$94,"Select a score (1-5) to display scoring criteria"),"")
A24: CX_003 | B24: CX | C24: Order Accuracy | E24: =IFERROR(XLOOKUP(A24&"_"&TEXT(D24,"0"),Setup_Parameters!$A$35:$A$94,Setup_Parameters!$B$35:$B$94,"Select a score (1-5) to display scoring criteria"),"")
A25: CX_004 | B25: CX | C25: Atmosphere & Seating | E25: =IFERROR(XLOOKUP(A25&"_"&TEXT(D25,"0"),Setup_Parameters!$A$35:$A$94,Setup_Parameters!$B$35:$B$94,"Select a score (1-5) to display scoring criteria"),"")
A26: OPS_001 | B26: Ops | C26: Barista Workflow Efficiency | E26: =IFERROR(XLOOKUP(A26&"_"&TEXT(D26,"0"),Setup_Parameters!$A$35:$A$94,Setup_Parameters!$B$35:$B$94,"Select a score (1-5) to display scoring criteria"),"")
A27: OPS_002 | B27: Ops | C27: Equipment Reliability | E27: =IFERROR(XLOOKUP(A27&"_"&TEXT(D27,"0"),Setup_Parameters!$A$35:$A$94,Setup_Parameters!$B$35:$B$94,"Select a score (1-5) to display scoring criteria"),"")
A28: OPS_003 | B28: Ops | C28: Counter Cleanliness | E28: =IFERROR(XLOOKUP(A28&"_"&TEXT(D28,"0"),Setup_Parameters!$A$35:$A$94,Setup_Parameters!$B$35:$B$94,"Select a score (1-5) to display scoring criteria"),"")
A29: OPS_004 | B29: Ops | C29: Menu & Stock Availability | E29: =IFERROR(XLOOKUP(A29&"_"&TEXT(D29,"0"),Setup_Parameters!$A$35:$A$94,Setup_Parameters!$B$35:$B$94,"Select a score (1-5) to display scoring criteria"),"")
A30: REV_001 | B30: Rev | C30: Menu Visibility & Upselling | E30: =IFERROR(XLOOKUP(A30&"_"&TEXT(D30,"0"),Setup_Parameters!$A$35:$A$94,Setup_Parameters!$B$35:$B$94,"Select a score (1-5) to display scoring criteria"),"")
A31: REV_002 | B31: Rev | C31: Peak Capacity Utilization | E31: =IFERROR(XLOOKUP(A31&"_"&TEXT(D31,"0"),Setup_Parameters!$A$35:$A$94,Setup_Parameters!$B$35:$B$94,"Select a score (1-5) to display scoring criteria"),"")
A32: REV_003 | B32: Rev | C32: Pricing Perception | E32: =IFERROR(XLOOKUP(A32&"_"&TEXT(D32,"0"),Setup_Parameters!$A$35:$A$94,Setup_Parameters!$B$35:$B$94,"Select a score (1-5) to display scoring criteria"),"")
A33: REV_004 | B33: Rev | C33: Secondary Spend Opportunity | E33: =IFERROR(XLOOKUP(A33&"_"&TEXT(D33,"0"),Setup_Parameters!$A$35:$A$94,Setup_Parameters!$B$35:$B$94,"Select a score (1-5) to display scoring criteria"),"")
A35: SHIFT 3: OFF-PEAK (18:00 – 19:00)
A36: Metric ID | B36: Dimension | C36: Metric Name | D36: Score (1-5) | E36: Scoring Criteria | F36: Auditor Notes
A37: CX_001 | B37: CX | C37: Service Friendliness | E37: =IFERROR(XLOOKUP(A37&"_"&TEXT(D37,"0"),Setup_Parameters!$A$35:$A$94,Setup_Parameters!$B$35:$B$94,"Select a score (1-5) to display scoring criteria"),"")
A38: CX_002 | B38: CX | C38: Queue & Wait Time | E38: =IFERROR(XLOOKUP(A38&"_"&TEXT(D38,"0"),Setup_Parameters!$A$35:$A$94,Setup_Parameters!$B$35:$B$94,"Select a score (1-5) to display scoring criteria"),"")
A39: CX_003 | B39: CX | C39: Order Accuracy | E39: =IFERROR(XLOOKUP(A39&"_"&TEXT(D39,"0"),Setup_Parameters!$A$35:$A$94,Setup_Parameters!$B$35:$B$94,"Select a score (1-5) to display scoring criteria"),"")
A40: CX_004 | B40: CX | C40: Atmosphere & Seating | E40: =IFERROR(XLOOKUP(A40&"_"&TEXT(D40,"0"),Setup_Parameters!$A$35:$A$94,Setup_Parameters!$B$35:$B$94,"Select a score (1-5) to display scoring criteria"),"")
A41: OPS_001 | B41: Ops | C41: Barista Workflow Efficiency | E41: =IFERROR(XLOOKUP(A41&"_"&TEXT(D41,"0"),Setup_Parameters!$A$35:$A$94,Setup_Parameters!$B$35:$B$94,"Select a score (1-5) to display scoring criteria"),"")
A42: OPS_002 | B42: Ops | C42: Equipment Reliability | E42: =IFERROR(XLOOKUP(A42&"_"&TEXT(D42,"0"),Setup_Parameters!$A$35:$A$94,Setup_Parameters!$B$35:$B$94,"Select a score (1-5) to display scoring criteria"),"")
A43: OPS_003 | B43: Ops | C43: Counter Cleanliness | E43: =IFERROR(XLOOKUP(A43&"_"&TEXT(D43,"0"),Setup_Parameters!$A$35:$A$94,Setup_Parameters!$B$35:$B$94,"Select a score (1-5) to display scoring criteria"),"")
...

Sheet Calc_Engine
A1: CALC ENGINE · All formulas locked · Hidden in client deliverable · Do not edit
A2: This sheet feeds the Dashboard. It is hidden via right-click > Hide after delivery.
A3: SECTION 1 – DIMENSION SCORE AVERAGES (per shift + overall)
A4: Dimension | B4: S1 Morning | C4: S2 Afternoon | D4: S3 Off-Peak | E4: Overall Avg | F4: Benchmark (from Setup)
A5: Customer Experience (CX) | B5: =IFERROR(AVERAGE(Input_Data!$D$7:$D$10),"") | C5: =IFERROR(AVERAGE(Input_Data!$D$22:$D$25),"") | D5: =IFERROR(AVERAGE(Input_Data!$D$37:$D$40),"") | E5: =IFERROR(AVERAGEIF(B5:D5,">0"),"") | F5: =IFERROR(Setup_Parameters!$B$14,"")
A6: Operations (Ops) | B6: =IFERROR(AVERAGE(Input_Data!$D$11:$D$14),"") | C6: =IFERROR(AVERAGE(Input_Data!$D$26:$D$29),"") | D6: =IFERROR(AVERAGE(Input_Data!$D$41:$D$44),"") | E6: =IFERROR(AVERAGEIF(B6:D6,">0"),"") | F6: =IFERROR(Setup_Parameters!$B$15,"")
A7: Revenue Opportunity (Rev) | B7: =IFERROR(AVERAGE(Input_Data!$D$15:$D$18),"") | C7: =IFERROR(AVERAGE(Input_Data!$D$30:$D$33),"") | D7: =IFERROR(AVERAGE(Input_Data!$D$45:$D$48),"") | E7: =IFERROR(AVERAGEIF(B7:D7,">0"),"") | F7: =IFERROR(Setup_Parameters!$B$16,"")
A9: SECTION 2 – WEIGHTED OVERALL SCORE & PERFORMANCE GRADE
A10: Active Store Type | B10: =Setup_Parameters!$B$4
A11: Overall Weighted Score (0.0 – 5.0) | B11: =IFERROR(SUMPRODUCT(CHOOSE(MATCH(Setup_Parameters!$B$4,{"Speed-First","Space-First"},0),Setup_Parameters!$B$8:$B$10,Setup_Parameters!$C$8:$C$10),IFERROR(E5:E7*1,0)),"")
A12: Performance Grade | B12: =IFERROR(IFS(B11>=4.5,"S",B11>=4.0,"A",B11>=3.0,"B",B11>=2.0,"C",B11<2.0,"F"),"")
A14: SECTION 3 – FINANCIAL LEAKAGE CALCULATOR
A15: Observed Lost Customers (Daily) | B15: =IFERROR(Input_Data!$D$51,0)
A16: Average Spend Per Customer (ASP) | B16: =IFERROR(Setup_Parameters!$E$4,4.50)
A17: Monthly Revenue Leakage | B17: =IFERROR(B15*B16*30,"")
A19: SECTION 4 – METRIC REPORT TABLE · Source for FILTER formula on Dashboard (named: Metric_Report_Range)
A20: Metric_ID | B20: Dimension | C20: Metric_Name | D20: Avg_Score | E20: Recommended_Action | F20: Is_RedFlag
A21: CX_001 | B21: CX | C21: Service Friendliness | D21: =IFERROR(AVERAGE(Input_Data!$D$7,Input_Data!$D$22,Input_Data!$D$37),"") | E21: Implement service standards training. Introduce daily briefing for hospitality KPIs. | F21: =IF(ISNUMBER(D21),D21<2.5,FALSE)
A22: CX_002 | B22: CX | C22: Queue & Wait Time | D22: =IFERROR(AVERAGE(Input_Data!$D$8,Input_Data!$D$23,Input_Data!$D$38),"") | E22: Deploy queue management system. Train staff on proactive ETA communication. | F22: =IF(ISNUMBER(D22),D22<2.5,FALSE)
A23: CX_003 | B23: CX | C23: Order Accuracy | D23: =IFERROR(AVERAGE(Input_Data!$D$9,Input_Data!$D$24,Input_Data!$D$39),"") | E23: Introduce order verification checklist. Review drink ticketing workflow end-to-end. | F23: =IF(ISNUMBER(D23),D23<2.5,FALSE)
A24: CX_004 | B24: CX | C24: Atmosphere & Seating | D24: =IFERROR(AVERAGE(Input_Data!$D$10,Input_Data!$D$25,Input_Data!$D$40),"") | E24: Conduct seating audit. Address noise and temperature. Schedule deep-clean cycle. | F24: =IF(ISNUMBER(D24),D24<2.5,FALSE)
A25: OPS_001 | B25: Ops | C25: Barista Workflow Efficiency | D25: =IFERROR(AVERAGE(Input_Data!$D$11,Input_Data!$D$26,Input_Data!$D$41),"") | E25: Map current workflow. Implement station layout redesign. Cross-train all staff. | F25: =IF(ISNUMBER(D25),D25<2.5,FALSE)
A26: OPS_002 | B26: Ops | C26: Equipment Reliability | D26: =IFERROR(AVERAGE(Input_Data!$D$12,Input_Data!$D$27,Input_Data!$D$42),"") | E26: Schedule preventive maintenance. Build equipment checklist. Source backup units. | F26: =IF(ISNUMBER(D26),D26<2.5,FALSE)
A27: OPS_003 | B27: Ops | C27: Counter Cleanliness | D27: =IFERROR(AVERAGE(Input_Data!$D$13,Input_Data!$D$28,Input_Data!$D$43),"") | E27: Implement hourly cleaning schedule. Assign counter ownership per staff member. | F27: =IF(ISNUMBER(D27),D27<2.5,FALSE)
A28: OPS_004 | B28: Ops | C28: Menu & Stock Availability | D28: =IFERROR(AVERAGE(Input_Data!$D$14,Input_Data!$D$29,Input_Data!$D$44),"") | E28: Deploy real-time inventory tracking. Implement 80/20 par-level restocking system. | F28: =IF(ISNUMBER(D28),D28<2.5,FALSE)
A29: REV_001 | B29: Rev | C29: Menu Visibility & Upselling | D29: =IFERROR(AVERAGE(Input_Data!$D$15,Input_Data!$D$30,Input_Data!$D$45),"") | E29: Redesign menu board layout. Script upsell prompts. Introduce combo promotions. | F29: =IF(ISNUMBER(D29),D29<2.5,FALSE)
A30: REV_002 | B30: Rev | C30: Peak Capacity Utilization | D30: =IFERROR(AVERAGE(Input_Data!$D$16,Input_Data!$D$31,Input_Data!$D$46),"") | E30: Implement reservation or queue-ahead system. Install peak-hour promotional signage. | F30: =IF(ISNUMBER(D30),D30<2.5,FALSE)
A31: REV_003 | B31: Rev | C31: Pricing Perception | D31: =IFERROR(AVERAGE(Input_Data!$D$17,Input_Data!$D$32,Input_Data!$D$47),"") | E31: Review pricing vs local competitive set. Strengthen premium product storytelling. | F31: =IF(ISNUMBER(D31),D31<2.5,FALSE)
A32: REV_004 | B32: Rev | C32: Secondary Spend Opportunity | D32: =IFERROR(AVERAGE(Input_Data!$D$18,Input_Data!$D$33,Input_Data!$D$48),"") | E32: Introduce grab-and-go retail section. Train staff on cross-selling protocol. | F32: =IF(ISNUMBER(D32),D32<2.5,FALSE)

Sheet Dashboard_Report
A1: CAFÉ AUDIT REPORT · 3-Dimension Diagnostic Dashboard
A2: =IFERROR("Café: "&Input_Data!$B$2,"") | C2: =IFERROR("Date: "&TEXT(Input_Data!$D$2,"DD-MMM-YYYY"),"") | E2: =IFERROR("Type: "&Input_Data!$B$3,"") | G2: =IFERROR("Auditor: "&Input_Data!$F$2,"")
A4: OVERALL SCORE | D4: PERFORMANCE GRADE | G4: REV. LEAKAGE / MO.
A5: =IFERROR(TEXT(Calc_Engine!$B$11,"0.0")&" / 5.0","–") | D5: =IFERROR(Calc_Engine!$B$12,"–") | G5: =IFERROR(TEXT(Calc_Engine!$B$17,"$#,##0"),"$–")
A6: Weighted composite · CX + Ops + Rev | D6: S >= 4.5 | A >= 4.0 | B >= 3.0 | C >= 2.0 | F < 2.0 | G6: Alert if > $500 / month
A7: =IFERROR("CX "&TEXT(Calc_Engine!$E$5,"0.00")&" / 5.0","CX –") | D7: =IFERROR("OPS "&TEXT(Calc_Engine!$E$6,"0.00")&" / 5.0","OPS –") | G7: =IFERROR("REV "&TEXT(Calc_Engine!$E$7,"0.00")&" / 5.0","REV –")
A10: ACTION ITEMS · Red Flag Metrics (Avg Score < 2.5) · Powered by FILTER formula
A11: Metric ID | B11: Dim. | C11: Metric Name | D11: Score | E11: Recommended Action
A12: =IFERROR(FILTER(Calc_Engine!$A$21:$E$32,Calc_Engine!$F$21:$F$32=TRUE,"No high-risk issues identified. All metrics meet the 2.5 threshold."),"–")
A24: PERFORMANCE RADAR · Actual Score vs. Industry Benchmark (3 Dimensions)
A25: [ BUCKET B — RADAR / SPIDER CHART ] Chart Type: Radar (Filled) — 3 axis categories Category Labels: Customer Experience | Operations | Revenue Opportunity Series 1 'Actual Score': Calc_Engine!E5:E7 Series 2 'Industry Benchmark': Setup_Parameters!B14:B16 Style Guide: Series 1 fill = #2251FF at 30% transparency | border = #2251FF solid 1.5pt Series 2 fill = none | border = #888888 dashed 1pt Chart background = transparent | Remove chart border Legend position = bottom centre How to build: 1. Insert > Chart > Radar > Filled Radar 2. Select Data: set Series 1 & 2 as above 3. Apply colours from Style Guide above 4. Resize chart to cover this placeholder area (~A25:H44)
A45: Generated by Café Audit System · Confidential Diagnostic Report · Not for External Distribution
